<?xml version="1.0"?>
<robot name="mira">
<!--URDF uses SI Units: meters, radians and kilograms-->
<!-- Three basic geometry shapes:
<cylinder radius="meters" length="meters"/>
<box size="x_length y_length z_length"/>
<sphere radius="meters"/>
-->

<!--
rosservice call /gazebo/delete_model "model_name: 'mira'"
roslaunch my_mira_description spawn_mira.launch" 
-->
    

    <!--This activates the gazebo control plugin for the Mira namespace. This namespace will be set in the main spawn launch file.-->
    <gazebo>
        <plugin name="gazebo_ros_control" filename="libgazebo_ros_control.so">
            <robotNamespace>/mira</robotNamespace>
        </plugin>
    </gazebo>


<!-- ################### LINK Definitions ############################# -->
<!-- ################### LINK Definitions ############################# -->
<!-- ################### LINK Definitions ############################# -->
<!-- ################### LINK Definitions ############################# -->
<!-- ################### LINK Definitions ############################# -->

    <link 
    name="base_link">
        <inertial>
            <origin xyz="0 0 0" rpy="0 0 0"/>
            <mass value="0.18" />
            <inertia ixx="0.0002835" ixy="0.0" ixz="0.0" iyy="0.0002835" iyz="0.0" izz="0.000324"/>
        </inertial>
        <collision>
            <origin xyz="0 0 0" rpy="0 0 0"/>
            <geometry>
                <cylinder radius="0.06" length="0.09"/>
            </geometry>
        </collision>
        <visual>
            <origin rpy="0.0 0 0" xyz="0 0 0"/>
            <geometry>
                <!--<cylinder radius="0.06" length="0.09"/> -->
                <mesh filename="package://mira_description/models/mira/meshes/mira_body_v3.dae"/>
                <!--When i used $MODEL the inertials became extremely fucked up, and it started gaining momentum and started spinning around like a top (not in place)-->
                <!--<mesh model="package://my_mira_description/models/mira/meshes/mira_body_v3.dae"/>-->
            </geometry>
             <!--<material name="green"/> -->
        </visual>
    </link>

    <link name="roll_M1_link">
        <!-- Inertial for gazebo to take it into account, Put 1gr weight -->
        <inertial>
            <origin xyz="0 0 0" rpy="0 0 0"/>
            <mass value="0.001" />
            <inertia ixx="2.70833333333e-08" ixy="0.0" ixz="0.0" iyy="2.70833333333e-08" iyz="0.0" izz="5e-08"/>
        </inertial>
        <visual>
            <origin rpy="0 0 0" xyz="0 0 0"/>
            <geometry>
                <cylinder length="0.005" radius="0.01"/>
            </geometry>
            <!--<material name="red"/>-->
        </visual>
    </link>

    <link name="pitch_M2_link">
        <!-- Inertial for gazebo to take it into account, Put 1gr weight -->
        <inertial>
            <origin xyz="0 0 0" rpy="0 0 0"/>
            <mass value="0.001" />
            <inertia ixx="2.70833333333e-08" ixy="0.0" ixz="0.0" iyy="2.70833333333e-08" iyz="0.0" izz="5e-08"/>
        </inertial>
        <visual>
            <origin rpy="0 0 0" xyz="0 0 0"/>
            <geometry>
                <cylinder length="0.005" radius="0.01"/>
            </geometry>
            <!--<material name="green"/>-->
        </visual>
    </link>

    <link name="yaw_M3_link">
        <!-- Inertial for gazebo to take it into account, Put 1gr weight -->
        <inertial>
            <origin xyz="0 0 0" rpy="0 0 0"/>
            <mass value="0.001" />
            <inertia ixx="2.70833333333e-08" ixy="0.0" ixz="0.0" iyy="2.70833333333e-08" iyz="0.0" izz="5e-08"/>
        </inertial>
        <visual>
            <origin rpy="0 0 0" xyz="0 0 0"/>
            <geometry>
                <cylinder length="0.005" radius="0.01"/>
            </geometry>
            <!--<material name="blue"/>-->
        </visual>
    </link>

    <link
    name="head_link">
        <inertial>
            <origin xyz="0 0 0" rpy="0 0 0"/>
            <mass value="0.02" />
            <inertia ixx="2.61666666667e-05" ixy="0.0" ixz="0.0" iyy="2.61666666667e-05" iyz="0.0" izz="3.6e-05"/>
        </inertial>
        <collision>
            <origin xyz="0 0 0.015" rpy="0 0 0"/>
            <geometry>
                <!-- <cylinder xyz="0 0 0.015" rpy="0 0 0"/> -->
                <sphere radius="0.06"/>
            </geometry>
        </collision>
        <visual>
            <origin xyz="0 0 0" rpy="0.0 0 0"/>
            <geometry>
                <!--<sphere radius="0.06"/> -->
                <mesh filename="package://mira_description/models/mira/meshes/mira_head_v5.dae"/>
            </geometry>
            <!-- <material name="white"/> -->
        </visual>
    </link>

    <link name="left_eye_link">
        <!-- Inertial for gazebo to take it into account, Put 1gr weight -->
        <inertial>
            <origin xyz="0 0 0" rpy="0 0 0"/>
            <mass value="0.001" />
            <inertia ixx="9.1875e-09" ixy="0.0" ixz="0.0" iyy="9.1875e-09" iyz="0.0" izz="1.378125e-08"/>
        </inertial>
		<visual>
            <origin rpy="0.0 0 0" xyz="0 0 0"/>
            <geometry>
                <!--<cylinder radius="0.00525" length="0.00525"/> -->
                <mesh filename="package://mira_description/models/mira/meshes/mira_eye_v4.dae"/>
            </geometry>
        </visual>
	</link>

    <link
    name="right_eye_link">
        <!-- Inertial for gazebo to take it into account, Put 1gr weight -->
        <inertial>
            <origin xyz="0 0 0" rpy="0 0 0"/>
            <mass value="0.001" />
            <inertia ixx="9.1875e-09" ixy="0.0" ixz="0.0" iyy="9.1875e-09" iyz="0.0" izz="1.378125e-08"/>
        </inertial>
        <visual>
            <origin rpy="0.0 0 0" xyz="0 0 0"/>
            <geometry>
                <!--<cylinder radius="0.00525" length="0.00525"/> -->
                <mesh filename="package://mira_description/models/mira/meshes/mira_eye_v4.dae"/>
            </geometry>
             <!--<material name="green"/> -->
        </visual>
    </link>

    <link name="camera_link">
        <!-- Inertial for gazebo to take it into account, Put 1gr weight -->
        <inertial>
            <origin xyz="0 0 0" rpy="0 0 0"/>
            <mass value="0.001" />
            <inertia ixx="9.1875e-09" ixy="0.0" ixz="0.0" iyy="9.1875e-09" iyz="0.0" izz="1.378125e-08"/>
        </inertial>
		<visual>
            <origin rpy="0.0 0 0" xyz="0 0 0"/>
            <geometry>
                <box size="0.0005 0.0005 0.0005"/>
            </geometry>
            <!--<material name="green"/>-->
        </visual>
	</link>

<!-- ################### JOINT Definitions ############################# -->
<!-- ################### JOINT Definitions ############################# -->
<!-- ################### JOINT Definitions ############################# -->
<!-- ################### JOINT Definitions ############################# -->
<!-- ################### JOINT Definitions ############################# -->

     <!--Joint types: revolute, continuous, prismatic, fixed, floating, planar-->
     <joint name="roll_joint" type="revolute">
     	<parent link="base_link"/>
     	<child link="roll_M1_link"/>
         <origin xyz="0.0023 0 -0.0005" rpy="0 0 0"/>
        <!--lower and upper are angle limits in radians-->
        <limit lower="-0.2" upper="0.2" effort="0.1" velocity="0.005"/>
        <!--1 0 0 Defines X as the axis of rotation-->
        <axis xyz="1 0 0"/>
    </joint>

    <joint name="pitch_joint" type="revolute">
    	<parent link="roll_M1_link"/>
    	<child link="pitch_M2_link"/>
    	<origin xyz="0 0 0" rpy="0 -1.5708 0"/>
        <limit lower="0" upper="0.44" effort="0.1" velocity="0.005"/>
        <axis xyz="0 1 0"/>
	</joint>

    <joint name="yaw_joint" type="continuous">
    	<parent link="pitch_M2_link"/>
    	<child link="yaw_M3_link"/>
        <origin xyz="0.01 0 0" rpy="0 1.5708 0"/>
        <limit effort="0.1" velocity="0.01"/>
        <axis xyz="0 0 1"/>
	</joint>

    <joint
    name="base_head_joint" type="fixed">
        <parent link="yaw_M3_link"/>
        <child link="head_link"/>
        <origin xyz="0 0 0" rpy="0 0 0"/>
    </joint>

    <joint name="head_lefteye_joint" type="fixed">
        <parent link="head_link"/>
        <child link="left_eye_link"/>
        <origin xyz="0.0095 0.057 0.0085" rpy="-1.5708 0 0"/>
    </joint>

    <joint name="head_righteye_joint" type="fixed">
        <parent link="head_link"/>
        <child link="right_eye_link"/>
        <origin xyz="-0.0095 0.057 0.0085" rpy="-1.5708 0 0"/>
    </joint>

    <joint
    name="head_camera_joint" type="fixed">
        <parent link="head_link"/>
        <child link="camera_link"/>
        <origin xyz="0 0.057 0.0255" rpy="0 0 0"/>
    </joint>

    
<!-- ################### TRANSMISSION Definitions ############################# -->
<!-- ################### TRANSMISSION Definitions ############################# -->
<!-- ################### TRANSMISSION Definitions ############################# -->
<!-- ################### TRANSMISSION Definitions ############################# -->
<!-- ################### TRANSMISSION Definitions ############################# -->

<!--Here you define the name of the transmission, which will have to be unique through the URDF file.-->
    <transmission name="transmission_roll_joint">
        <type>transmission_interface/SimpleTransmission</type>
        <!--Here you link the joint to the transmission and select the hardware interface, which also only has an effort interface working.-->
        <joint name="roll_joint">
            <hardwareInterface>EffortJointInterface</hardwareInterface>
        </joint>
        <!--Here you set a unique name for the actuator and again select the hardware interface. As for the reduction, it's self-explanatory.-->
        <actuator name="motor_roll_joint">
            <hardwareInterface>EffortJointInterface</hardwareInterface>
            <mechanicalReduction>1</mechanicalReduction>
        </actuator>
    </transmission>

    <!--Here you define the name of the transmission, which will have to be unique through the URDF file.-->
    <transmission name="transmission_pitch_joint">
        <type>transmission_interface/SimpleTransmission</type>
        <!--Here you link the joint to the transmission and select the hardware interface, which also only has an effort interface working.-->
        <joint name="pitch_joint">
            <hardwareInterface>EffortJointInterface</hardwareInterface>
        </joint>
        <!--Here you set a unique name for the actuator and again select the hardware interface. As for the reduction, it's self-explanatory.-->
        <actuator name="motor_pitch_joint">
            <hardwareInterface>EffortJointInterface</hardwareInterface>
            <mechanicalReduction>1</mechanicalReduction>
        </actuator>
    </transmission>

    <!--Here you define the name of the transmission, which will have to be unique through the URDF file.-->
    <transmission name="transmission_yaw_joint">
        <type>transmission_interface/SimpleTransmission</type>
        <!--Here you link the joint to the transmission and select the hardware interface, which also only has an effort interface working.-->
        <joint name="yaw_joint">
            <hardwareInterface>EffortJointInterface</hardwareInterface>
        </joint>
        <!--Here you set a unique name for the actuator and again select the hardware interface. As for the reduction, it's self-explanatory.-->
        <actuator name="motor_yaw_joint">
            <hardwareInterface>EffortJointInterface</hardwareInterface>
            <mechanicalReduction>1</mechanicalReduction>
        </actuator>
    </transmission>
    
<!-- ################### MATERIALS Definitions ############################# -->
<!-- ################### MATERIALS Definitions ############################# -->
<!-- ################### MATERIALS Definitions ############################# -->
<!-- ################### MATERIALS Definitions ############################# -->
<!-- ################### MATERIALS Definitions ############################# -->

    <!--<material name="blue">-->
    <!--    <color rgba="0 0 0.8 1"/>-->
    <!--</material>-->
    <!--<material name="red">-->
    <!--    <color rgba="0.8 0 0 1"/>-->
    <!--</material>-->
    <material name="green">
        <color rgba="0 0.8 0 1"/>
    </material>
    
    <!--<gazebo reference="base_link">-->
    <!--    <kp>1000.0</kp>-->
    <!--    <kd>10.0</kd>-->
    <!--    <mu1>10.0</mu1>-->
    <!--    <mu2>10.0</mu2>-->
    <!--    <material>Gazebo/Red</material>-->
    <!--</gazebo>-->

    <!-- This is for color and physical properties in Gazebo, color won't work with the material tag in gazebo
    only for URDF coloring -->
    <gazebo reference="roll_M1_link">
        <kp>1000.0</kp>
        <kd>10.0</kd>
        <mu1>10.0</mu1>
        <mu2>10.0</mu2>
        <material>Gazebo/Red</material>
    </gazebo>

    <!-- This is for color and physical properties in Gazebo, color won't work with the material tag in gazebo
    only for URDF coloring -->
    <gazebo reference="pitch_M2_link">
        <kp>1000.0</kp>
        <kd>10.0</kd>
        <mu1>10.0</mu1>
        <mu2>10.0</mu2>
        <material>Gazebo/Green</material>
    </gazebo>

    <!-- This is for color and physical properties in Gazebo, color won't work with the material tag in gazebo
    only for URDF coloring -->
    <gazebo reference="yaw_M3_link">
        <kp>1000.0</kp>
        <kd>10.0</kd>
        <mu1>10.0</mu1>
        <mu2>10.0</mu2>
        <material>Gazebo/Blue</material>
    </gazebo>

    <gazebo reference="left_eye_link">
        <material>Gazebo/Green</material>
    </gazebo>

    <gazebo reference="right_eye_link">
        <material>Gazebo/Green</material>
    </gazebo>

    <gazebo reference="camera_link">
        <material>Gazebo/Green</material>
    </gazebo>

    
<!-- ################### SENSOR Definitions ############################# -->
<!-- ################### SENSOR Definitions ############################# -->
<!-- ################### SENSOR Definitions ############################# -->

    <!-- camera -->
    <gazebo reference="camera_link">
        <sensor type="camera" name="camera1">
            <update_rate>15.0</update_rate>
            <camera name="head">
                <pose>0 0 0 0 0 1.57</pose>
                <horizontal_fov>1.3962634</horizontal_fov>
                <image>
                    <width>400</width>
                    <height>400</height>
                    <format>R8G8B8</format>
                </image>
                <clip>
                    <near>0.01</near>
                    <far>100</far>
                </clip>
                <noise>
                    <type>gaussian</type>
                    <stddev>0.007</stddev>
                </noise>
            </camera>
            
            <plugin name="camera_controller" filename="libgazebo_ros_camera.so">
                <alwaysOn>true</alwaysOn>
                <updateRate>0.0</updateRate>
                <cameraName>mira/camera1</cameraName>
                <imageTopicName>image_raw</imageTopicName>
                <cameraInfoTopicName>camera_info</cameraInfoTopicName>
                <frameName>camera_link</frameName>
                <hackBaseline>0.07</hackBaseline>
                <distortionK1>0.0</distortionK1>
                <distortionK2>0.0</distortionK2>
                <distortionK3>0.0</distortionK3>
                <distortionT1>0.0</distortionT1>
                <distortionT2>0.0</distortionT2>
            </plugin>
        </sensor>
    </gazebo>

<!-- +++++++++++++++++++++++++++++++++++++++++++++++++++++++++++++++++++ -->
        
    
    

    

    
    
    


    
    
    
</robot>
        
