<?xml version="1.0" ?>
<!-- =================================================================================== -->
<!-- |    This document was autogenerated by xacro from /home/user/catkin_ws/src/my_gurdy_description/robots/gurdy.urdf.xacro | -->
<!-- |    EDITING THIS FILE BY HAND IS NOT RECOMMENDED                                 | -->
<!-- =================================================================================== -->
<!-- <robot name="gurdy"> -->
<robot name="gurdy" xmlns:xacro="http://www.ros.org/wiki/xacro">
  <!--You will also need the dimensions of the the basic geometry to have some idea of the way that everything is connected, and the collision elements geometry:-->
  <!--For base_link there is no inertia needed because its a non-functional element-->
  <!--base_link :         box size="0.01 0.01 0.01"                   mass=None, -->
  <!--head_link :         cylinder radius="0.05"      length="0.04"   mass value="0.01"-->
  <!--upperleg_links :   cylinder radius="0.0025"    length="0.06"   mass value="0.01"-->
  <!--lowerleg_links :   cylinder radius="0.0015"    length="0.06"   mass value="0.01"-->
  <!--foot_links :        sphere   radius="0.008"                     mass value="0.01"-->
  <!--Friction is vital in the foot links. Try different values and see the effect on locomotion. These are some orientative values:-->
  <!--kp = 1000.0-->
  <!--kd = 1000.0-->
  <!--mu1 = 10.0-->
  <!--mu2 = 10.0-->
  <!--PID are tricky. Use rqt_reconfigure to get correct values. These are some orientative values:-->
  <!--{p: 3.0, i: 1.0, d: 0.0}-->
  <!-- ################### XACRO Definitions ############################# -->
  <!-- ################### XACRO Definitions ############################# -->
  <!-- ################### XACRO Definitions ############################# -->
  <!-- ################### XACRO Definitions ############################# -->
  <!-- ################### XACRO Definitions ############################# -->
  <!-- MUST ALWAYS GO BEFORE XACRO DEFINITIONS -->
  <gazebo>
    <plugin filename="libgazebo_ros_control.so" name="gazebo_ros_control">
      <robotNamespace>/gurdy</robotNamespace>
    </plugin>
  </gazebo>
  <!-- <xacro:macro name="generate_transmission" params="parent_link child_link link_num" >
    <transmission name="transmission_${parent_link}_${child_link}${link_num}">
        <type>transmission_interface/SimpleTransmission</type>
        <joint name="${parent_link}_${child_link}_joint">
            <hardwareInterface>EffortJointInterface</hardwareInterface>
        </joint>
        <actuator name="motor_${parent_link}_${child_link}">
            <hardwareInterface>EffortJointInterface</hardwareInterface>
            <mechanicalReduction>1</mechanicalReduction>
        </actuator>
    </transmission>
</xacro:macro>

<xacro:generate_transmission parent_link=""> -->
  <!-- ################### LINK Definitions ############################# -->
  <!-- ################### LINK Definitions ############################# -->
  <!-- ################### LINK Definitions ############################# -->
  <!-- ################### LINK Definitions ############################# -->
  <!-- ################### LINK Definitions ############################# -->
  <link name="base_link">
    <!--<inertial>-->
    <!--    <origin/>-->
    <!--    <mass value="0.001"/>-->
    <!--    <inertia ixx="1.66666666667e-08" ixy="0.0" ixz="0.0" iyy="1.66666666667e-08" iyz="0.0" izz="1.66666666667e-08"/>-->
    <!--</inertial>-->
    <collision>
      <origin rpy="0 0 0" xyz="0 0 0"/>
      <geometry>
        <box size="0.01 0.01 0.01"/>
      </geometry>
    </collision>
    <visual>
      <origin rpy="0 0 0" xyz="0 0 0"/>
      <geometry>
        <box size="0.01 0.01 0.01"/>
      </geometry>
    </visual>
  </link>
  <link name="head_link">
    <inertial>
      <origin rpy="0 0 0" xyz="0 0 0.02"/>
      <mass value="0.01"/>
      <!-- <inertia ixx="7.58333333333e-06" ixy="0.0" ixz="0.0" iyy="7.58333333333e-06" iyz="0.0" izz="1.25e-05"/> -->
      <inertia ixx="7.58333333333e-06" ixy="0.0" ixz="0.0" iyy="7.58333333333e-06" iyz="0.0" izz="1.25e-05"/>
    </inertial>
    <collision>
      <origin rpy="0 0 0" xyz="0 0 0.02"/>
      <geometry>
        <cylinder length="0.04" radius="0.05"/>
        <!-- <mesh filename="package://gurdy_description/models/gurdy/meshes/gurdy_head_v2.dae"/> -->
      </geometry>
    </collision>
    <visual>
      <origin rpy="0 0 0" xyz="0 0 0"/>
      <geometry>
        <mesh filename="package://gurdy_description/models/gurdy/meshes/gurdy_head_v2.dae"/>
      </geometry>
    </visual>
  </link>
  <link name="upperleg_M1_link">
    <!--UPPER-->
    <inertial>
      <origin rpy="0 0 0" xyz="0 0 0.02"/>
      <!--UPPER-->
      <mass value="0.01"/>
      <!-- ORIGINAL value taken from Inertial_calculator.py -->
      <!-- <inertia ixx="3.015625e-06" ixy="0.0" ixz="0.0" iyy="3.015625e-06" iyz="0.0" izz="3.125e-08"/> -->
      <!-- SOLUTION INERTIA ++++ WAY LESS TWITCHING -->
      <inertia ixx="3.015625e-05" ixy="0.0" ixz="0.0" iyy="3.015625e-05" iyz="0.0" izz="3.125e-07"/>
    </inertial>
    <collision>
      <origin rpy="0 0 0" xyz="0 0 0.02"/>
      <!--UPPER-->
      <geometry>
        <cylinder length="0.06" radius="0.0025"/>
      </geometry>
    </collision>
    <visual>
      <origin rpy="0 0 0" xyz="0 0 0"/>
      <geometry>
        <mesh filename="package://gurdy_description/models/gurdy/meshes/gurdy_higherleg_v2.dae"/>
      </geometry>
    </visual>
  </link>
  <link name="upperleg_M2_link">
    <!--UPPER-->
    <inertial>
      <origin rpy="0 0 0" xyz="0 0 0.02"/>
      <!--UPPER-->
      <mass value="0.01"/>
      <!-- ORIGINAL value taken from Inertial_calculator.py -->
      <!-- <inertia ixx="3.015625e-06" ixy="0.0" ixz="0.0" iyy="3.015625e-06" iyz="0.0" izz="3.125e-08"/> -->
      <!-- SOLUTION INERTIA ++++ WAY LESS TWITCHING -->
      <inertia ixx="3.015625e-05" ixy="0.0" ixz="0.0" iyy="3.015625e-05" iyz="0.0" izz="3.125e-07"/>
    </inertial>
    <collision>
      <origin rpy="0 0 0" xyz="0 0 0.02"/>
      <!--UPPER-->
      <geometry>
        <cylinder length="0.06" radius="0.0025"/>
      </geometry>
    </collision>
    <visual>
      <origin rpy="0 0 0" xyz="0 0 0"/>
      <geometry>
        <mesh filename="package://gurdy_description/models/gurdy/meshes/gurdy_higherleg_v2.dae"/>
      </geometry>
    </visual>
  </link>
  <link name="upperleg_M3_link">
    <!--UPPER-->
    <inertial>
      <origin rpy="0 0 0" xyz="0 0 0.02"/>
      <!--UPPER-->
      <mass value="0.01"/>
      <!-- ORIGINAL value taken from Inertial_calculator.py -->
      <!-- <inertia ixx="3.015625e-06" ixy="0.0" ixz="0.0" iyy="3.015625e-06" iyz="0.0" izz="3.125e-08"/> -->
      <!-- SOLUTION INERTIA ++++ WAY LESS TWITCHING -->
      <inertia ixx="3.015625e-05" ixy="0.0" ixz="0.0" iyy="3.015625e-05" iyz="0.0" izz="3.125e-07"/>
    </inertial>
    <collision>
      <origin rpy="0 0 0" xyz="0 0 0.02"/>
      <!--UPPER-->
      <geometry>
        <cylinder length="0.06" radius="0.0025"/>
      </geometry>
    </collision>
    <visual>
      <origin rpy="0 0 0" xyz="0 0 0"/>
      <geometry>
        <mesh filename="package://gurdy_description/models/gurdy/meshes/gurdy_higherleg_v2.dae"/>
      </geometry>
    </visual>
  </link>
  <link name="lowerleg_M1_link">
    <!--UPPER-->
    <inertial>
      <origin rpy="0 0 0" xyz="0 0 0.03"/>
      <!--LOWER-->
      <mass value="0.01"/>
      <!-- ORIGINAL value taken from Inertial_calculator.py -->
      <!-- <inertia ixx="3.005625e-06" ixy="0.0" ixz="0.0" iyy="3.005625e-06" iyz="0.0" izz="1.125e-08"/> -->
      <!-- SOLUTION INERTIA ++++  -->
      <inertia ixx="3.005625e-05" ixy="0.0" ixz="0.0" iyy="3.005625e-05" iyz="0.0" izz="1.125e-07"/>
    </inertial>
    <collision>
      <origin rpy="0 0 0" xyz="0 0 0.03"/>
      <!--LOWER-->
      <geometry>
        <cylinder length="0.06" radius="0.0015"/>
      </geometry>
    </collision>
    <visual>
      <origin rpy="0 0 0" xyz="0 0 0"/>
      <geometry>
        <mesh filename="package://gurdy_description/models/gurdy/meshes/gurdy_lowerleg_v2.dae"/>
      </geometry>
    </visual>
  </link>
  <link name="lowerleg_M2_link">
    <!--UPPER-->
    <inertial>
      <origin rpy="0 0 0" xyz="0 0 0.03"/>
      <!--LOWER-->
      <mass value="0.01"/>
      <!-- ORIGINAL value taken from Inertial_calculator.py -->
      <!-- <inertia ixx="3.005625e-06" ixy="0.0" ixz="0.0" iyy="3.005625e-06" iyz="0.0" izz="1.125e-08"/> -->
      <!-- SOLUTION INERTIA ++++  -->
      <inertia ixx="3.005625e-05" ixy="0.0" ixz="0.0" iyy="3.005625e-05" iyz="0.0" izz="1.125e-07"/>
    </inertial>
    <collision>
      <origin rpy="0 0 0" xyz="0 0 0.03"/>
      <!--LOWER-->
      <geometry>
        <cylinder length="0.06" radius="0.0015"/>
      </geometry>
    </collision>
    <visual>
      <origin rpy="0 0 0" xyz="0 0 0"/>
      <geometry>
        <mesh filename="package://gurdy_description/models/gurdy/meshes/gurdy_lowerleg_v2.dae"/>
      </geometry>
    </visual>
  </link>
  <link name="lowerleg_M3_link">
    <!--UPPER-->
    <inertial>
      <origin rpy="0 0 0" xyz="0 0 0.03"/>
      <!--LOWER-->
      <mass value="0.01"/>
      <!-- ORIGINAL value taken from Inertial_calculator.py -->
      <!-- <inertia ixx="3.005625e-06" ixy="0.0" ixz="0.0" iyy="3.005625e-06" iyz="0.0" izz="1.125e-08"/> -->
      <!-- SOLUTION INERTIA ++++  -->
      <inertia ixx="3.005625e-05" ixy="0.0" ixz="0.0" iyy="3.005625e-05" iyz="0.0" izz="1.125e-07"/>
    </inertial>
    <collision>
      <origin rpy="0 0 0" xyz="0 0 0.03"/>
      <!--LOWER-->
      <geometry>
        <cylinder length="0.06" radius="0.0015"/>
      </geometry>
    </collision>
    <visual>
      <origin rpy="0 0 0" xyz="0 0 0"/>
      <geometry>
        <mesh filename="package://gurdy_description/models/gurdy/meshes/gurdy_lowerleg_v2.dae"/>
      </geometry>
    </visual>
  </link>
  <link name="footM1_link">
    <!--UPPER-->
    <inertial>
      <origin rpy="0 0 0" xyz="0 0 0.01"/>
      <!--FOOT-->
      <mass value="0.01"/>
      <!-- ORIGINAL value taken from Inertial_calculator.py -->
      <!-- <inertia ixx="2.56e-07" ixy="0.0" ixz="0.0" iyy="2.56e-07" iyz="0.0" izz="2.56e-07"/> -->
      <!-- SOLUTION INERTIA ++++  -->
      <inertia ixx="1.28e-06" ixy="0.0" ixz="0.0" iyy="1.28e-06" iyz="0.0" izz="1.28e-06"/>
    </inertial>
    <collision>
      <origin rpy="0 0 0" xyz="0 0 0.01"/>
      <!--FOOT-->
      <geometry>
        <sphere radius="0.008"/>
      </geometry>
    </collision>
    <visual>
      <origin rpy="0 0 0" xyz="0 0 0"/>
      <geometry>
        <sphere radius="0.008"/>
      </geometry>
    </visual>
  </link>
  <link name="footM2_link">
    <!--UPPER-->
    <inertial>
      <origin rpy="0 0 0" xyz="0 0 0.01"/>
      <!--FOOT-->
      <mass value="0.01"/>
      <!-- ORIGINAL value taken from Inertial_calculator.py -->
      <!-- <inertia ixx="2.56e-07" ixy="0.0" ixz="0.0" iyy="2.56e-07" iyz="0.0" izz="2.56e-07"/> -->
      <!-- SOLUTION INERTIA ++++  -->
      <inertia ixx="1.28e-06" ixy="0.0" ixz="0.0" iyy="1.28e-06" iyz="0.0" izz="1.28e-06"/>
    </inertial>
    <collision>
      <origin rpy="0 0 0" xyz="0 0 0.01"/>
      <!--FOOT-->
      <geometry>
        <sphere radius="0.008"/>
      </geometry>
    </collision>
    <visual>
      <origin rpy="0 0 0" xyz="0 0 0"/>
      <geometry>
        <sphere radius="0.008"/>
      </geometry>
    </visual>
  </link>
  <link name="footM3_link">
    <!--UPPER-->
    <inertial>
      <origin rpy="0 0 0" xyz="0 0 0.01"/>
      <!--FOOT-->
      <mass value="0.01"/>
      <!-- ORIGINAL value taken from Inertial_calculator.py -->
      <!-- <inertia ixx="2.56e-07" ixy="0.0" ixz="0.0" iyy="2.56e-07" iyz="0.0" izz="2.56e-07"/> -->
      <!-- SOLUTION INERTIA ++++  -->
      <inertia ixx="1.28e-06" ixy="0.0" ixz="0.0" iyy="1.28e-06" iyz="0.0" izz="1.28e-06"/>
    </inertial>
    <collision>
      <origin rpy="0 0 0" xyz="0 0 0.01"/>
      <!--FOOT-->
      <geometry>
        <sphere radius="0.008"/>
      </geometry>
    </collision>
    <visual>
      <origin rpy="0 0 0" xyz="0 0 0"/>
      <geometry>
        <sphere radius="0.008"/>
      </geometry>
    </visual>
  </link>
  <!-- ################### JOINT Definitions ############################# -->
  <!-- ################### JOINT Definitions ############################# -->
  <!-- ################### JOINT Definitions ############################# -->
  <!-- ################### JOINT Definitions ############################# -->
  <!-- ################### JOINT Definitions ############################# -->
  <joint name="base_head_joint" type="fixed">
    <parent link="base_link"/>
    <child link="head_link"/>
    <!-- <origin xyz="0 0 0" rpy="0 0 0"/> -->
    <!--Rest NOT NEEDED for FIXED joint-->
    <!--<limit lower="-0.2" upper="0.2" effort="1.0" velocity="0.005"/>-->
    <!--<axis xyz="0 0 0"/>-->
  </joint>
  <joint name="head_upperlegM1_joint" type="revolute">
    <parent link="head_link"/>
    <child link="upperleg_M1_link"/>
    <!--this is the Pitch value from the urdf to graphiz map pdf-->
    <!--<origin xyz="-0.02165 -0.0125 -0.008" rpy="3.14159 -1.05879e-22 0.523599"/>-->
    <!--This Pitch value is from solution-->
    <!--Haven't seen a difference-->
    <origin rpy="3.14159 0 0.523599" xyz="-0.02165 -0.0125 -0.008"/>
    <!--Rest NOT NEEDED for FIXED joint-->
    <limit effort="1.0" lower="-1.57" upper="0.0" velocity="0.005"/>
    <axis xyz="0 1 0"/>
  </joint>
  <joint name="head_upperlegM2_joint" type="revolute">
    <parent link="head_link"/>
    <child link="upperleg_M2_link"/>
    <origin rpy="3.14159 0 2.61799" xyz="0.02165 -0.0125 -0.008"/>
    <!--Rest NOT NEEDED for FIXED joint-->
    <limit effort="1.0" lower="-1.57" upper="0.0" velocity="0.005"/>
    <axis xyz="0 1 0"/>
  </joint>
  <joint name="head_upperlegM3_joint" type="revolute">
    <parent link="head_link"/>
    <child link="upperleg_M3_link"/>
    <origin rpy="3.14159 0 -1.5708" xyz="0 0.025 -0.008"/>
    <!--Rest NOT NEEDED for FIXED joint-->
    <limit effort="1.0" lower="-1.57" upper="0.0" velocity="0.005"/>
    <axis xyz="0 1 0"/>
  </joint>
  <joint name="upperlegM1_lowerlegM1_joint" type="revolute">
    <parent link="upperleg_M1_link"/>
    <child link="lowerleg_M1_link"/>
    <origin rpy="0 0 3.14159" xyz="0 0.0095 0.06"/>
    <limit effort="1.0" lower="-2.65" upper="0" velocity="0.005"/>
    <axis xyz="0 1 0"/>
  </joint>
  <joint name="upperlegM2_lowerlegM2_joint" type="revolute">
    <parent link="upperleg_M2_link"/>
    <child link="lowerleg_M2_link"/>
    <origin rpy="0 0 3.14159" xyz="0 0.0095 0.06"/>
    <limit effort="1.0" lower="-2.65" upper="0" velocity="0.005"/>
    <axis xyz="0 1 0"/>
  </joint>
  <joint name="upperlegM3_lowerlegM3_joint" type="revolute">
    <parent link="upperleg_M3_link"/>
    <child link="lowerleg_M3_link"/>
    <origin rpy="0 0 3.14159" xyz="0 0.0095 0.06"/>
    <limit effort="1.0" lower="-2.65" upper="0" velocity="0.005"/>
    <axis xyz="0 1 0"/>
  </joint>
  <joint name="basefoot_peg_M1_basefoot_peg_M1_joint_joint" type="fixed">
    <parent link="lowerleg_M1_link"/>
    <child link="footM1_link"/>
    <origin rpy="0 0 0" xyz="0 0 0.06"/>
    <!--Rest NOT NEEDED for FIXED joint-->
    <!--<limit lower="-2.65" upper="0" effort="1.0" velocity="0.005"/>-->
    <!--<axis xyz="0 1 0"/>-->
  </joint>
  <joint name="basefoot_peg_M2_basefoot_peg_M2_joint_joint" type="fixed">
    <parent link="lowerleg_M2_link"/>
    <child link="footM2_link"/>
    <origin rpy="0 0 0" xyz="0 0 0.06"/>
    <!--Rest NOT NEEDED for FIXED joint-->
    <!--<limit lower="-2.65" upper="0" effort="1.0" velocity="0.005"/>-->
    <!--<axis xyz="0 1 0"/>-->
  </joint>
  <joint name="basefoot_peg_M3_basefoot_peg_M3_joint_joint" type="fixed">
    <parent link="lowerleg_M3_link"/>
    <child link="footM3_link"/>
    <origin rpy="0 0 0" xyz="0 0 0.06"/>
    <!--Rest NOT NEEDED for FIXED joint-->
    <!--<limit lower="-2.65" upper="0" effort="1.0" velocity="0.005"/>-->
    <!--<axis xyz="0 1 0"/>-->
  </joint>
  <!-- ################### TRANSMISSION Definitions ############################# -->
  <!-- ################### TRANSMISSION Definitions ############################# -->
  <!-- ################### TRANSMISSION Definitions ############################# -->
  <!-- ################### TRANSMISSION Definitions ############################# -->
  <!-- ################### TRANSMISSION Definitions ############################# -->
  <!-- <transmission name="transmission_head_upperlegM1">
                <type>transmission_interface/SimpleTransmission</type>
                <joint name="head_upperlegM1_joint">
                    <hardwareInterface>EffortJointInterface</hardwareInterface>
                </joint>
                <actuator name="motor_head_upperlegM1">
                    <hardwareInterface>EffortJointInterface</hardwareInterface>
                    <mechanicalReduction>1</mechanicalReduction>
                </actuator>
            </transmission>

            <transmission name="transmission_head_upperlegM2">
                <type>transmission_interface/SimpleTransmission</type>
                <joint name="head_upperlegM2_joint">
                    <hardwareInterface>EffortJointInterface</hardwareInterface>
                </joint>
                <actuator name="motor_head_upperlegM2">
                    <hardwareInterface>EffortJointInterface</hardwareInterface>
                    <mechanicalReduction>1</mechanicalReduction>
                </actuator>
            </transmission>

            <transmission name="transmission_head_upperlegM3">
                <type>transmission_interface/SimpleTransmission</type>
                <joint name="head_upperlegM3_joint">
                    <hardwareInterface>EffortJointInterface</hardwareInterface>
                </joint>
                <actuator name="motor_head_upperlegM3">
                    <hardwareInterface>EffortJointInterface</hardwareInterface>
                    <mechanicalReduction>1</mechanicalReduction>
                </actuator>
            </transmission>

                    <transmission name="transmission_upperlegM1_lowerlegM1">
                        <type>transmission_interface/SimpleTransmission</type>
                        <joint name="upperlegM1_lowerlegM1_joint">
                            <hardwareInterface>EffortJointInterface</hardwareInterface>
                        </joint>
                        <actuator name="motor_upperlegM1_lowerlegM1">
                            <hardwareInterface>EffortJointInterface</hardwareInterface>
                            <mechanicalReduction>1</mechanicalReduction>
                        </actuator>
                    </transmission>

                    <transmission name="transmission_upperlegM2_lowerlegM2">
                        <type>transmission_interface/SimpleTransmission</type>
                        <joint name="upperlegM2_lowerlegM2_joint">
                            <hardwareInterface>EffortJointInterface</hardwareInterface>
                        </joint>
                        <actuator name="motor_upperlegM2_lowerlegM2">
                            <hardwareInterface>EffortJointInterface</hardwareInterface>
                            <mechanicalReduction>1</mechanicalReduction>
                        </actuator>
                    </transmission>

                    <transmission name="transmission_upperlegM3_lowerlegM3">
                        <type>transmission_interface/SimpleTransmission</type>
                        <joint name="upperlegM3_lowerlegM3_joint">
                            <hardwareInterface>EffortJointInterface</hardwareInterface>
                        </joint>
                        <actuator name="motor_upperlegM3_lowerlegM3">
                            <hardwareInterface>EffortJointInterface</hardwareInterface>
                            <mechanicalReduction>1</mechanicalReduction>
                        </actuator>
                    </transmission> -->
  <!-- ################### MATERIALS Definitions ############################# -->
  <!-- ################### MATERIALS Definitions ############################# -->
  <!-- ################### MATERIALS Definitions ############################# -->
  <!-- ################### MATERIALS Definitions ############################# -->
  <!-- ################### MATERIALS Definitions ############################# -->
  <gazebo reference="head_link">
    <mu1>10.0</mu1>
    <mu2>10.0</mu2>
  </gazebo>
  <!-- This is for color and physical properties in Gazebo, color won't work with the material tag in gazebo
                            only for URDF coloring -->
  <gazebo reference="footM1_link">
    <kp>1000.0</kp>
    <kd>1000.0</kd>
    <mu1>10.0</mu1>
    <mu2>10.0</mu2>
    <!--<material>Gazebo/Red</material>-->
    <material>Gazebo/White</material>
  </gazebo>
  <!-- This is for color and physical properties in Gazebo, color won't work with the material tag in gazebo
                            only for URDF coloring -->
  <gazebo reference="footM2_link">
    <kp>1000.0</kp>
    <kd>1000.0</kd>
    <mu1>10.0</mu1>
    <mu2>10.0</mu2>
    <!--<material>Gazebo/Green</material>-->
    <material>Gazebo/White</material>
  </gazebo>
  <!-- This is for color and physical properties in Gazebo, color won't work with the material tag in gazebo
                            only for URDF coloring -->
  <gazebo reference="footM3_link">
    <kp>1000.0</kp>
    <kd>1000.0</kd>
    <mu1>10.0</mu1>
    <mu2>10.0</mu2>
    <!--<material>Gazebo/Blue</material>-->
    <material>Gazebo/White</material>
  </gazebo>
  <!-- ################### SENSOR Definitions ############################# -->
  <!-- ################### SENSOR Definitions ############################# -->
  <!-- ################### SENSOR Definitions ############################# -->
  <!-- ################### SENSOR Definitions ############################# -->
  <!-- ################### SENSOR Definitions ############################# -->
  <!-- <gazebo>
        <plugin name="gazebo_ros_imu_controller" filename="libgazebo_ros_imu.so">
            <robotNamespace>/gurdy</robotNamespace>
            <topicName>imu/data</topicName>
            <serviceName>imu/service</serviceName>
            <bodyName>base_link</bodyName>
            <gaussianNoise>0</gaussianNoise>
            <rpyOffsets>0 0 0</rpyOffsets>
            <updateRate>10.0</updateRate>
            <alwaysOn>true</alwaysOn>
            <gaussianNoise>0</gaussianNoise>
        </plugin>
</gazebo> -->
</robot>

